# 예외 처리

## 구분
- throw
- try...catch

### throw
예외를 처리하는 구문, 사용되는 값을 포함하는 표현을 명시해야 합니다.
``` javascript
throw "Error2";
throw 42;
throw true;
throw {toString: () => "I'm an object!"};
```
### try...catch + finally
예외를 처리하는 문법, 시도할 블록을 표시하고, 예외가 발생했을 때, 하나 이상의 반응을 명시합니다.
try 블록은 **1개 이상**의 시도 구문이 있어야 합니다.
catch 블록은 try에서 예외가 발생했을 때 실행할 **0개 이상**의 처리 구문이 있어야 합니다.
finally 블록은 try와 catch 블록이 모두 끝났을 때 예외가 발생하든 안하든 **무조건 실행**됩니다.

try...catch 구문 안에 throw를 넣어 오류를 반환하고 이 오류를 catch가 가져갈 수 있습니다.
``` javascript
try {
    throw "Error!";
} catch (e) {
    // e = "Error!"
    console.log(e);
    // Error!
} finally {
    console.log("finally");
    // finally
}
```